<?xml version='1.0' encoding='utf-8'?>
<robot name="WAM-V">
  <link name="wamv/base_link">
  </link>
  <joint name="wamv/dummy_joint" type="fixed">
    <parent link="wamv/base_link" />
    <child link="wamv/dummy_link" />
  </joint>

  <link name="wamv/dummy_link">
    <visual>
      <geometry>
        <mesh filename="package://wamv_description/models/WAM-V-Base/mesh/WAM-V-Base.dae" scale="0.265306 0.408333 0.408333" />
      </geometry>
    </visual>

    <collision name="left_float">
      <origin rpy="0 1.57 0" xyz="-0.028155 0.171738 0.033347" />
      <geometry>
        <cylinder length="4" radius="0.2" />
      </geometry>
    </collision>
    <collision name="left_mid_float">
      <origin rpy="0 1.38 0" xyz="0.130216 0.171738 0.050021" />
      <geometry>
        <cylinder length="0.5" radius="0.17" />
      </geometry>
    </collision>
    <collision name="left_front_float">
      <origin rpy="0 1.3 0" xyz="0.161891 0.171738 0.066694" />
      <geometry>
        <cylinder length="0.45" radius="0.12" />
      </geometry>
    </collision>

    <collision name="front_left_beam_lower">
      <origin rpy="0.78 0 0" xyz="0.063349 0.141726 0.166736" />
      <geometry>
        <cylinder length="0.5" radius="0.04" />
      </geometry>
    </collision>
    <collision name="front_left_beam_upper">
      <origin rpy="1.35 0 0" xyz="0.063349 0.100042 0.196748" />
      <geometry>
        <cylinder length="0.2" radius="0.04" />
      </geometry>
    </collision>

    <collision name="mid_left_beam_lower">
      <origin rpy="0.1 0.25 0" xyz="-0.045752 0.165069 0.116715" />
      <geometry>
        <cylinder length="0.45" radius="0.03" />
      </geometry>
    </collision>
    <collision name="mid_left_beam_medium">
      <origin rpy="0.75 0.25 0" xyz="-0.040121 0.145060 0.175073" />
      <geometry>
        <cylinder length="0.32" radius="0.03" />
      </geometry>
    </collision>
    <collision name="mid_left_beam_upper">
      <origin rpy="1.35 0.25 0" xyz="-0.038713 0.108379 0.195081" />
      <geometry>
        <cylinder length="0.3" radius="0.03" />
      </geometry>
    </collision>

    <collision name="rear_left_beam_lower">
      <origin rpy="0 -0.15 0" xyz="-0.052087 0.171738 0.116715" />
      <geometry>
        <cylinder length="0.45" radius="0.03" />
      </geometry>
    </collision>
    <collision name="rear_left_beam_medium">
      <origin rpy="0.75 -0.15 0" xyz="-0.055606 0.151730 0.175073" />
      <geometry>
        <cylinder length="0.32" radius="0.03" />
      </geometry>
    </collision>
    <collision name="rear_left_beam_upper">
      <origin rpy="1.45 -0.15 0" xyz="-0.057014 0.111713 0.196748" />
      <geometry>
        <cylinder length="0.3" radius="0.03" />
      </geometry>
    </collision>

    <collision name="left_joint">
      <origin rpy="0 -0.6 0" xyz="0.040825 0.171738 0.100042" />
      <geometry>
        <box size="0.65 0.2 0.1" />
      </geometry>
    </collision>

    <collision name="right_float">
      <origin rpy="0 1.57 0" xyz="-0.028155 -0.171738 0.033347" />
      <geometry>
        <cylinder length="4" radius="0.2" />
      </geometry>
    </collision>
    <collision name="right_mid_float">
      <origin rpy="0 1.38 0" xyz="0.130216 -0.171738 0.050021" />
      <geometry>
        <cylinder length="0.5" radius="0.17" />
      </geometry>
    </collision>
    <collision name="right_front_float">
      <origin rpy="0 1.3 0" xyz="0.161891 -0.171738 0.066694" />
      <geometry>
        <cylinder length="0.45" radius="0.12" />
      </geometry>
    </collision>

    <collision name="front_right_beam_lower">
      <origin rpy="-0.78 0 0" xyz="0.063349 -0.141726 0.166736" />
      <geometry>
        <cylinder length="0.5" radius="0.04" />
      </geometry>
    </collision>
    <collision name="front_right_beam_upper">
      <origin rpy="-1.35 0 0" xyz="0.063349 -0.100042 0.196748" />
      <geometry>
        <cylinder length="0.2" radius="0.04" />
      </geometry>
    </collision>

    <collision name="mid_right_beam_lower">
      <origin rpy="-0.1 0.25 0" xyz="-0.045752 -0.165069 0.116715" />
      <geometry>
        <cylinder length="0.45" radius="0.03" />
      </geometry>
    </collision>
    <collision name="mid_right_beam_medium">
      <origin rpy="-0.75 0.25 0" xyz="-0.040121 -0.145060 0.175073" />
      <geometry>
        <cylinder length="0.32" radius="0.03" />
      </geometry>
    </collision>
    <collision name="mid_right_beam_upper">
      <origin rpy="-1.35 0.25 0" xyz="-0.038713 -0.108379 0.195081" />
      <geometry>
        <cylinder length="0.3" radius="0.03" />
      </geometry>
    </collision>

    <collision name="rear_right_beam_lower">
      <origin rpy="0 -0.15 0" xyz="-0.052087 -0.171738 0.116715" />
      <geometry>
        <cylinder length="0.45" radius="0.03" />
      </geometry>
    </collision>
    <collision name="rear_right_beam_medium">
      <origin rpy="-0.75 -0.15 0" xyz="-0.055606 -0.151730 0.175073" />
      <geometry>
        <cylinder length="0.32" radius="0.03" />
      </geometry>
    </collision>
    <collision name="rear_right_beam_upper">
      <origin rpy="-1.45 -0.15 0" xyz="-0.057014 -0.111713 0.196748" />
      <geometry>
        <cylinder length="0.3" radius="0.03" />
      </geometry>
    </collision>

    <collision name="right_joint">
      <origin rpy="0 -0.6 0" xyz="0.040825 -0.171738 0.100042" />
      <geometry>
        <box size="0.65 0.2 0.1" />
      </geometry>
    </collision>

    <collision name="top_base">
      <origin rpy="0 0 0" xyz="0.000000 -0.000000 0.208420" />
      <geometry>
        <box size="1.85 1 0.1" />
      </geometry>
    </collision>
    <inertial>

      <mass value="38.0" />
      <inertia ixx="120.0" ixy="0.0" ixz="0.0" iyy="393" iyz="0.0" izz="6.25" />
    </inertial>
  </link>
  <link name="wamv/left_engine_link">
    <visual>
      <geometry>
        <mesh filename="package://wamv_description/models/engine/mesh/engine.dae" scale="0.265306 0.408333 0.408333" />
      </geometry>
    </visual>
    <collision name="left_engine_vertical_axis_collision">
      <origin rpy="0 0 0" xyz="-0.011262 0.000000 -0.040017" />
      <geometry>
        <box size="0.2 0.15 0.83" />
      </geometry>
    </collision>
    <collision name="left_engine_rear_end_collision">
      <origin rpy="0 0 0" xyz="-0.023932 0.000000 0.020008" />
      <geometry>
        <box size="0.12 0.15 0.12" />
      </geometry>
    </collision>
    <inertial>
      <mass value="0.01" />
      <inertia ixx="0.889245" ixy="0.0" ixz="0.0" iyy="0.911125" iyz="0.0" izz="0.078125" />
    </inertial>
  </link>
  <link name="wamv/left_propeller_link">
    <visual>
      <geometry>
        <mesh filename="package://wamv_description/models/propeller/mesh/propeller.dae" scale="0.265306 0.408333 0.408333" />
      </geometry>
    </visual>
    <collision name="left_propeller_collision">
      <origin rpy="0 1.57 0" xyz="-0.005631 0.000000 0.000000" />
      <geometry>
        <cylinder length="0.18" radius="0.24" />
      </geometry>
    </collision>
    <inertial>
      <mass value="0.01" />
      <inertia ixx="0.008545" ixy="0.0" ixz="0.0" iyy="0.008545" iyz="0.0" izz="0.0144" />
    </inertial>
  </link>
  <joint name="wamv/left_chasis_engine_joint" type="revolute">
    <axis xyz="0 0 1" />
    <limit effort="10" lower="-3.141592653589793" upper="3.141592653589793" velocity="10" />
    <origin rpy="0.0 0.0 0.0" xyz="-0.6 0.37 0.11" />
    <parent link="wamv/base_link" />
    <child link="wamv/left_engine_link" />
  </joint>
  <joint name="wamv/left_engine_propeller_joint" type="continuous">
    <axis rpy="0 0 0" xyz="1 0 0" />
    <parent link="wamv/left_engine_link" />
    <child link="wamv/left_propeller_link" />
    <origin rpy="0 0 0" xyz="-0.019579 0.000000 -0.084930" />
    <limit effort="100" velocity="100" />
    <dynamics damping="0.05" friction="0.05" />
  </joint>
  <link name="wamv/right_engine_link">
    <visual>
      <geometry>
        <mesh filename="package://wamv_description/models/engine/mesh/engine.dae" scale="0.265306 0.408333 0.408333" />
      </geometry>
    </visual>
    <collision name="right_engine_vertical_axis_collision">
      <origin rpy="0 0 0" xyz="-0.011262 0.000000 -0.040017" />
      <geometry>
        <box size="0.2 0.15 0.83" />
      </geometry>
    </collision>
    <collision name="right_engine_rear_end_collision">
      <origin rpy="0 0 0" xyz="-0.023932 0.000000 0.020008" />
      <geometry>
        <box size="0.12 0.15 0.12" />
      </geometry>
    </collision>
    <inertial>
      <mass value="0.01" />
      <inertia ixx="0.889245" ixy="0.0" ixz="0.0" iyy="0.911125" iyz="0.0" izz="0.078125" />
    </inertial>
  </link>
  <link name="wamv/right_propeller_link">
    <visual>
      <geometry>
        <mesh filename="package://wamv_description/models/propeller/mesh/propeller.dae" scale="0.265306 0.408333 0.408333" />
      </geometry>
    </visual>
    <collision name="right_propeller_collision">
      <origin rpy="0 1.57 0" xyz="-0.005631 0.000000 0.000000" />
      <geometry>
        <cylinder length="0.18" radius="0.24" />
      </geometry>
    </collision>
    <inertial>
      <mass value="0.01" />
      <inertia ixx="0.008545" ixy="0.0" ixz="0.0" iyy="0.008545" iyz="0.0" izz="0.0144" />
    </inertial>
  </link>
  <joint name="wamv/right_chasis_engine_joint" type="revolute">
    <axis xyz="0 0 1" />
    <limit effort="10" lower="-3.141592653589793" upper="3.141592653589793" velocity="10" />
    <origin rpy="0.0 0.0 0.0" xyz="-0.6 -0.37 0.11"/>
    <parent link="wamv/base_link" />
    <child link="wamv/right_engine_link" />
  </joint>
  <joint name="wamv/right_engine_propeller_joint" type="continuous">
    <axis rpy="0 0 0" xyz="1 0 0" />
    <parent link="wamv/right_engine_link" />
    <child link="wamv/right_propeller_link" />
    <origin rpy="0 0 0" xyz="-0.019579 0.000000 -0.084930" />
    <limit effort="100" velocity="100" />
    <dynamics damping="0.05" friction="0.05" />
  </joint>
  <gazebo>
    <plugin filename="libusv_gazebo_thrust_plugin.so" name="wamv_gazebo_thrust">
      <cmdTimeout>1.0</cmdTimeout>
      <robotNamespace>wamv</robotNamespace>
      <thruster>

        <linkName>wamv/left_propeller_link</linkName>
        <propJointName>wamv/left_engine_propeller_joint</propJointName>
        <engineJointName>wamv/left_chasis_engine_joint</engineJointName>
        <cmdTopic>thrusters/left_thrust_cmd</cmdTopic>
        <angleTopic>thrusters/left_thrust_angle</angleTopic>
        <enableAngle>False</enableAngle>

        <mappingType>1</mappingType>
        <maxCmd>1.0</maxCmd>
        <maxForceFwd>20.0</maxForceFwd>
        <maxForceRev>-20.0</maxForceRev>
        <maxAngle>1.5707963267948966</maxAngle>
      </thruster>
      <thruster>

        <linkName>wamv/right_propeller_link</linkName>
        <propJointName>wamv/right_engine_propeller_joint</propJointName>
        <engineJointName>wamv/right_chasis_engine_joint</engineJointName>
        <cmdTopic>thrusters/right_thrust_cmd</cmdTopic>
        <angleTopic>thrusters/right_thrust_angle</angleTopic>
        <enableAngle>True</enableAngle>

        <mappingType>1</mappingType>
        <maxCmd>1.0</maxCmd>
        <maxForceFwd>20.0</maxForceFwd>
        <maxForceRev>-20.0</maxForceRev>
        <maxAngle>1.5707963267948966</maxAngle>
      </thruster>
    </plugin>
  </gazebo>

  <gazebo>
    <plugin filename="libusv_gazebo_dynamics_plugin.so" name="usv_dynamics_wamv_dynamics_plugin">
      <bodyName>wamv/base_link</bodyName>

      <waterLevel>0</waterLevel>
      <waterDensity>997.8</waterDensity>

      <xDotU>1.9</xDotU>
      <yDotV>29.3171</yDotV>
      <nDotR>4.2155</nDotR>

      <xU>26.43</xU>
      <xUU>0.0</xUU>
      <yV>72.64</yV>
      <yVV>0.0</yVV>
      <nR>22.96</nR>
      <nRR>0.0</nRR>


      <hullRadius>0.213</hullRadius>
      <boatWidth>0.98</boatWidth>
      <boatLength>1.3</boatLength>

      <length_n>2</length_n>

      <wave_model>ocean_waves</wave_model>
    </plugin>
  </gazebo>

  <gazebo>
    <plugin name="p3d_plugin_wamv" filename="libgazebo_ros_p3d.so">
      <bodyName>wamv/base_link</bodyName>
      <frameName>map</frameName>
      <updateRate>50.0</updateRate>
      <topicName>wamv/p3d_position</topicName>
      <xyzOffset>0 0 0</xyzOffset>
      <rpyOffset>0 0 0</rpyOffset>
      <gaussianNoise>0.0</gaussianNoise>
    </plugin>
  </gazebo>

</robot>
